Traceback (most recent call last):
  File "/APP/APP/23_gpt-pilot/gpt-pilot/main.py", line 32, in <module>
    sys.exit(run_pythagora())
             ~~~~~~~~~~~~~^^
  File "/APP/APP/23_gpt-pilot/gpt-pilot/core/cli/main.py", line 315, in run_pythagora
    success = run(async_main(ui, db, args))
  File "/usr/lib/python3.13/asyncio/runners.py", line 195, in run
    return runner.run(main)
           ~~~~~~~~~~^^^^^^
  File "/usr/lib/python3.13/asyncio/runners.py", line 118, in run
    return self._loop.run_until_complete(task)
           ~~~~~~~~~~~~~~~~~~~~~~~~~~~~~^^^^^^
  File "/usr/lib/python3.13/asyncio/base_events.py", line 706, in run_until_complete
    self.run_forever()
    ~~~~~~~~~~~~~~~~^^
  File "/usr/lib/python3.13/asyncio/base_events.py", line 677, in run_forever
    self._run_once()
    ~~~~~~~~~~~~~~^^
  File "/usr/lib/python3.13/asyncio/base_events.py", line 1996, in _run_once
    event_list = self._selector.select(timeout)
  File "/usr/lib/python3.13/selectors.py", line 452, in select
    fd_event_list = self._selector.poll(timeout, max_ev)
  File "/APP/APP/23_gpt-pilot/gpt-pilot/core/cli/main.py", line 294, in signal_handler
    sync_cleanup(ui)
    ~~~~~~~~~~~~^^^^
  File "/APP/APP/23_gpt-pilot/gpt-pilot/core/cli/main.py", line 35, in sync_cleanup
    asyncio.run(cleanup(ui))
    ~~~~~~~~~~~^^^^^^^^^^^^^
  File "/usr/lib/python3.13/asyncio/runners.py", line 191, in run
    raise RuntimeError(
        "asyncio.run() cannot be called from a running event loop")
RuntimeError: asyncio.run() cannot be called from a running event loop
